<?xml version="1.0" ?>
<!-- =================================================================================== -->
<!-- |    This document was autogenerated by xacro from car.xacro                      | -->
<!-- |    EDITING THIS FILE BY HAND IS NOT RECOMMENDED                                 | -->
<!-- =================================================================================== -->
<robot name="agbot_car">
  <!-- Gazebo ros2_control plugin -->
  <gazebo>
    
        ?
        
    <plugin filename="libgazebo_ros_diff_drive.so" name="differential_drive_controller">
      <robot_param>robot_description</robot_param>
      <robot_param_node>robot_state_publisher</robot_param_node>
      <parameters>/home/albert/ag_car_ws/install/car_controller/share/car_controller/config/car_controllers.yaml</parameters>
      <controller_manager_prefix_node_name>controller_manager</controller_manager_prefix_node_name>
      <update_rate>100</update_rate>
      <num_wheel_pairs>2</num_wheel_pairs>
      <left_joint>left_front_wheel_joint</left_joint>
      <right_joint>right_front_wheel_joint</right_joint>
      <left_joint>left_rear_wheel_joint</left_joint>
      <right_joint>right_rear_wheel_joint</right_joint>
      <wheel_separation>0.358</wheel_separation>
      <wheel_diameter>0.068</wheel_diameter>
      <max_wheel_torque>200.0</max_wheel_torque>
      <max_wheel_acceleration>10.0</max_wheel_acceleration>
      <publish_odom>true</publish_odom>
      <publish_odom_tf>true</publish_odom_tf>
      <publish_wheel_tf>true</publish_wheel_tf>
      <odometry_topic>odom</odometry_topic>
      <odometry_frame>odom</odometry_frame>
      <robot_base_frame>base_footprint</robot_base_frame>
    </plugin>
  </gazebo>
  <gazebo reference="rgb_camera_link">
    <sensor name="camera_sensor" type="camera">
      <pose>0 0 0 0 0 0</pose>
      <visualize>true</visualize>
      <update_rate>60.0</update_rate>
      <camera>
        <horizontal_fov>1.089</horizontal_fov>
        <image>
          <format>R8G8B8</format>
          <width>1024</width>
          <height>768</height>
        </image>
        <clip>
          <near>0.05</near>
          <far>8.0</far>
        </clip>
      </camera>
      <plugin filename="libgazebo_ros_camera.so" name="camera_controller_base">
        <frame_name>rgb_camera_optical_b</frame_name>
      </plugin>
    </sensor>
  </gazebo>
  <gazebo reference="laser_link">
    <sensor name="laser" type="ray">
      <pose> 0 0 0 0 0 0 </pose>
      <visualize>true</visualize>
      <update_rate>10</update_rate>
      <ray>
        <scan>
          <horizontal>
            <samples>640</samples>
            <min_angle>-3.14</min_angle>
            <max_angle>3.14</max_angle>
          </horizontal>
          <vertical>
            <samples>1</samples>
            <min_angle>0</min_angle>
            <max_angle>0</max_angle>
          </vertical>
        </scan>
        <range>
          <min>0.3</min>
          <max>12</max>
        </range>
      </ray>
      <plugin filename="libgazebo_ros_ray_sensor.so" name="laser_controller">
        <ros>
          <argument>~/out:=scan</argument>
        </ros>
        <output_type>sensor_msgs/LaserScan</output_type>
        <frame_name>laser_frame</frame_name>
      </plugin>
    </sensor>
  </gazebo>
  <!-- Robot Body -->
  <gazebo reference="base_link">
    <material>Gazebo/Blue</material>
  </gazebo>
  <gazebo reference="front_axel">
    <material>Gazebo/FlatBlack</material>
  </gazebo>
  <gazebo reference="rear_axel">
    <material>Gazebo/FlatBlack</material>
  </gazebo>
  <gazebo reference="left_front_wheel_link">
    <material>Gazebo/Grey</material>
    <mu1 value="0.8"/>
    <mu2 value="0.8"/>
  </gazebo>
  <gazebo reference="right_front_wheel_link">
    <material>Gazebo/Grey</material>
    <mu1 value="0.8"/>
    <mu2 value="0.8"/>
  </gazebo>
  <gazebo reference="left_rear_wheel_link">
    <material>Gazebo/Grey</material>
    <mu1 value="0.8"/>
    <mu2 value="0.8"/>
  </gazebo>
  <gazebo reference="right_rear_wheel_link">
    <material>Gazebo/Grey</material>
    <mu1 value="0.8"/>
    <mu2 value="0.8"/>
  </gazebo>
  <gazebo reference="rgb_camera_link">
    <material>Gazebo/SkyBlue</material>
  </gazebo>
  <gazebo reference="mast_link">
    <material>Gazebo/Purple</material>
  </gazebo>
  <ros2_control name="RobotSystem" type="system">
    <hardware>
      <plugin>gazebo_ros2_control/GazeboSystem</plugin>
    </hardware>
    <joint name="left_front_wheel_joint">
      <command_interface name="velocity"/>
      <state_interface name="position"/>
      <state_interface name="velocity"/>
    </joint>
    <joint name="right_front_wheel_joint">
      <command_interface name="velocity"/>
      <state_interface name="position"/>
      <state_interface name="velocity"/>
    </joint>
    <joint name="left_rear_wheel_joint">
      <command_interface name="velocity"/>
      <state_interface name="position"/>
      <state_interface name="velocity"/>
    </joint>
    <joint name="right_rear_wheel_joint">
      <command_interface name="velocity"/>
      <state_interface name="position"/>
      <state_interface name="velocity"/>
    </joint>
  </ros2_control>
  <!-- Init colour -->
  <material name="black">
    <color rgba="0.0 0.0 0.0 1.0"/>
  </material>
  <material name="dark">
    <color rgba="0.3 0.3 0.3 1.0"/>
  </material>
  <material name="light_black">
    <color rgba="0.4 0.4 0.4 1.0"/>
  </material>
  <material name="blue">
    <color rgba="0.0 0.0 0.8 1.0"/>
  </material>
  <material name="green">
    <color rgba="0.0 0.8 0.0 1.0"/>
  </material>
  <material name="grey">
    <color rgba="0.5 0.5 0.5 1.0"/>
  </material>
  <material name="ClearGrey">
    <color rgba="0.2 0.2 0.2 0.75"/>
  </material>
  <material name="orange">
    <color rgba="1.0 0.4235 0.0392 1.0"/>
  </material>
  <material name="brown">
    <color rgba="0.8706 0.8118 0.7647 1.0"/>
  </material>
  <material name="white">
    <color rgba="1.0 1.0 1.0 1.0"/>
  </material>
  <material name="yellow">
    <color rgba="1.0 0.93 0.7 1"/>
  </material>
  <material name="purple">
    <color rgba="0.4 0.23 0.72 1"/>
  </material>
  <material name="turquoise">
    <color rgba="0.05 0.737 0.690 1.0"/>
  </material>
  <material name="skyblue">
    <color rgba="0.2 1.0 1.0"/>
  </material>
  <material name="pink">
    <color rgba="1.0 0 1.0 1.0"/>
  </material>
  <material name="red">
    <color rgba="1 0 0 1"/>
  </material>
  <material name="darkmaroon">
    <color rgba="0.23529411764705882 0.0 0.03137254901960784 1.0"/>
  </material>
  <material name="maroon">
    <color rgba="0.396078431372549 0.0 0.12941176470588237 1.0"/>
  </material>
  <!-- Robot Body -->
  <link name="base_footprint">
    </link>
  <link name="base_link">
    <visual>
      <geometry>
        <box size="0.45 0.225 0.15"/>
      </geometry>
      <origin rpy="0 0 0" xyz="0 0 0.075"/>
      <material name="maroon"/>
    </visual>
    <collision>
      <geometry>
        <box size="0.49500000000000005 0.24750000000000003 0.165"/>
      </geometry>
      <origin rpy="0 0 0" xyz="0 0 0.075"/>
    </collision>
    <inertial>
      <origin rpy="0 0 0" xyz="0 0 0.075"/>
      <mass value="18.0"/>
      <inertia ixx="0.3375" ixy="0" ixz="0" iyy="0.37968750000000007" iyz="0" izz="0.1096875"/>
    </inertial>
  </link>
  <link name="caster_wheel_link">
    <visual>
      <geometry>
        <sphere radius="0.034"/>
      </geometry>
      <origin rpy="0 0 0" xyx="0.15 0 0.034"/>
      <material name="yellow"/>
    </visual>
    <collision>
      <geometry>
        <sphere radius="0.034"/>
      </geometry>
      <origin rpy="0 0 0" xyx="0.15 0 0.034"/>
    </collision>
    <inertial>
      <origin rpy="0 0 0" xyz="0.15 0 0"/>
      <mass value="0.2"/>
      <inertia ixx="9.248000000000001e-05" ixy="0" ixz="0" iyy="9.248000000000001e-05" iyz="0" izz="9.248000000000001e-05"/>
    </inertial>
  </link>
  <link name="left_rear_wheel_link">
    <visual>
      <geometry>
        <mesh filename="file:///home/albert/rad_ws/install/agbot_full_description/share/agbot_full_description/meshes/left_tire.stl" scale="0.002 0.002 0.002"/>
      </geometry>
      <origin rpy="0 0 0" xyz="0 0 0"/>
      <material name="black"/>
    </visual>
    <collision>
      <geometry>
        <mesh filename="file:///home/albert/rad_ws/install/agbot_full_description/share/agbot_full_description/meshes/left_tire.stl" scale="0.002 0.002 0.002"/>
      </geometry>
      <origin rpy="0 0 0" xyz="0 0 0"/>
    </collision>
    <inertial>
      <origin rpy="1.5707963267948966 -1.5707963267948966 0" xyz="0 0 0"/>
      <mass value="1.0"/>
      <inertia ixx="0.0004973333333333334" ixy="0" ixz="0" iyy="0.0004973333333333334" iyz="0" izz="0.0005780000000000001"/>
    </inertial>
  </link>
  <link name="right_rear_wheel_link">
    <visual>
      <geometry>
        <mesh filename="file:///home/albert/rad_ws/install/agbot_full_description/share/agbot_full_description/meshes/right_tire.stl" scale="0.002 0.002 0.002"/>
      </geometry>
      <origin rpy="0 0 0" xyz="0 0 0"/>
      <material name="black"/>
    </visual>
    <collision>
      <geometry>
        <mesh filename="file:///home/albert/rad_ws/install/agbot_full_description/share/agbot_full_description/meshes/right_tire.stl" scale="0.002 0.002 0.002"/>
      </geometry>
      <origin rpy="0 0 0" xyz="0 0 0"/>
    </collision>
    <inertial>
      <origin rpy="1.5707963267948966 -1.5707963267948966 0" xyz="0 0 0"/>
      <mass value="1.0"/>
      <inertia ixx="0.0004973333333333334" ixy="0" ixz="0" iyy="0.0004973333333333334" iyz="0" izz="0.0005780000000000001"/>
    </inertial>
  </link>
  <link name="rgb_camera_optical_link">
    </link>
  <link name="rgb_camera_link">
    <inertial>
      <origin rpy="0 0 0" xyz="0 0 0"/>
      <mass value="0.001"/>
      <inertia ixx="1.0" ixy="0.0" ixz="0.0" iyy="1.0" iyz="0.0" izz="1.0"/>
    </inertial>
    <visual>
      <origin rpy="0 1.5707963267948966 0" xyz="0 -0.035 0.035"/>
      <geometry>
        <mesh filename="file:///home/albert/rad_ws/install/agbot_full_description/share/agbot_full_description/meshes/pi_camera.STL" scale="0.0025 0.0025 0.0025"/>
      </geometry>
      <material name="grey"/>
    </visual>
    <collision>
      <origin rpy="0 0 0" xyz="0.2 0 0"/>
      <geometry>
        <mesh filename="file:///home/albert/rad_ws/install/agbot_full_description/share/agbot_full_description/meshes/pi_camera.STL" scale="0.0025 0.0025 0.0025"/>
      </geometry>
    </collision>
  </link>
  <link name="mast_link">
    <visual>
      <origin rpy="0 0 0" xyz="0 0 0.05"/>
      <geometry>
        <box size="0.05 0.05 0.1"/>
      </geometry>
      <material name="pink"/>
    </visual>
    <collision>
      <geometry>
        <box size="0.05 0.05 0.1"/>
      </geometry>
      <origin rpy="0 0 0" xyz="0 0 0"/>
    </collision>
    <inertial>
      <origin rpy="0 0 0" xyz="0 0 0"/>
      <mass value="0.005"/>
      <inertia ixx="5.208333333333335e-06" ixy="0" ixz="0" iyy="2.083333333333334e-06" iyz="0" izz="5.208333333333335e-06"/>
    </inertial>
  </link>
  <link name="laser_frame_link">       
    </link>
  <link name="laser_link">
    <visual>
      <geometry>
        <cylinder length="0.1" radius="0.025"/>
      </geometry>
      <origin rpy="0 0 0" xyz="0 0 0"/>
      <material name="red"/>
    </visual>
    <collision>
      <geometry>
        <cylinder length="0.1" radius="0.025"/>
      </geometry>
      <origin rpy="0 0 0" xyz="0 0 0"/>
    </collision>
    <inertial>
      <origin rpy="0 0 0" xyz="0 0 0"/>
      <mass value="0.1"/>
      <inertia ixx="9.895833333333334e-05" ixy="0" ixz="0" iyy="9.895833333333334e-05" iyz="0" izz="3.125000000000001e-05"/>
    </inertial>
  </link>
  <!-- Joint Descriptions -->
  <joint name="base_joint" type="fixed">
    <parent link="base_footprint"/>
    <child link="base_link"/>
    <origin rpy="0 0 0" xyz="0 0 0.034"/>
  </joint>
  <joint name="base_caster_wheel_joint" type="fixed">
    <parent link="base_link"/>
    <child link="caster_wheel_link"/>
    <origin rpy="0 0 0" xyz="0.15 0 0"/>
  </joint>
  <joint name="right_rear_wheel_joint" type="continuous">
    <parent link="base_link"/>
    <child link="right_rear_wheel_link"/>
    <origin rpy="0 0 0" xyz="0 0 0.154"/>
    <axis xyz="0 1 0"/>
  </joint>
  <joint name="left_rear_wheel_joint" type="continuous">
    <parent link="base_link"/>
    <child link="left_rear_wheel_link"/>
    <origin ryp="0 0 0" xyz="0 0 -0.154"/>
    <axis xyz="0 1 0"/>
  </joint>
  <joint name="camera_optical_joint" type="fixed">
    <parent link="base_link"/>
    <child link="rgb_camera_optical_link"/>
    <origin rpy="0 0 0" xyz="0.225 0 0.135"/>
  </joint>
  <joint name="rgb_camera_joint" type="fixed">
    <parent link="rgb_camera_optical_link"/>
    <child link="rgb_camera_link"/>
    <origin rpy="0 0 0" xyz="0 0 0"/>
  </joint>
  <joint name="base_mast_joint" type="fixed">
    <parent link="base_link"/>
    <child link="mast_link"/>
    <origin rpy="0 0 0" xyz="0.175 0 0.15"/>
  </joint>
  <joint name="laser_frame_joint" type="fixed">
    <parent link="mast_link"/>
    <child link="laser_frame_link"/>
    <origin rpy="0 0 0" xyz="0 0 0.1"/>
  </joint>
  <joint name="laser_joint" type="fixed">
    <parent link="laser_frame_link"/>
    <child link="laser_link"/>
    <origin rpy="0 0 0" xyz="0 0 0"/>
  </joint>
  <transmission name="transmission_right_front_wheel_joint">
    <!-- <plugin>transmission_interface/DifferentialTransmission</plugin> -->
    <plugin>transmission_interface/SimpleTransmission</plugin>
    <actuator name="motor_right_front_wheel_joint" role="actuator1"/>
    <joint name="right_front_wheel_joint" role="joint1">
      <mechanical_reduction>1.0</mechanical_reduction>
    </joint>
  </transmission>
  <transmission name="transmission_left_front_wheel_joint">
    <!-- <plugin>transmission_interface/DifferentialTransmission</plugin> -->
    <plugin>transmission_interface/SimpleTransmission</plugin>
    <actuator name="motor_left_front_wheel_joint" role="actuator1"/>
    <joint name="left_front_wheel_joint" role="joint1">
      <mechanical_reduction>1.0</mechanical_reduction>
    </joint>
  </transmission>
  <transmission name="transmission_right_rear_wheel_joint">
    <!-- <plugin>transmission_interface/DifferentialTransmission</plugin> -->
    <plugin>transmission_interface/SimpleTransmission</plugin>
    <actuator name="motor_right_rear_wheel_joint" role="actuator1"/>
    <joint name="right_rear_wheel_joint" role="joint1">
      <mechanical_reduction>1.0</mechanical_reduction>
    </joint>
  </transmission>
  <transmission name="transmission_left_rear_wheel_joint">
    <!-- <plugin>transmission_interface/DifferentialTransmission</plugin> -->
    <plugin>transmission_interface/SimpleTransmission</plugin>
    <actuator name="motor_left_rear_wheel_joint" role="actuator1"/>
    <joint name="left_rear_wheel_joint" role="joint1">
      <mechanical_reduction>1.0</mechanical_reduction>
    </joint>
  </transmission>
</robot>
